# Promise 的源码分析

## 简易版
先排除 resolvePromise 方法的影响, 分析最简单的调用
``` js
function Promise(executor) {
  var self = this
  self.status = 'pending'
  self.onResolvedCallback = []
  self.onRejectedCallback = []

  function resolve(value) {
    setTimeout(function () { // 异步执行所有的回调函数
      if (self.status === 'pending') {
        self.status = 'resolved'
        self.data = value
        for (var i = 0; i < self.onResolvedCallback.length; i++) {
          self.onResolvedCallback[i](value)
        }
      }
    })
  }

  function reject(reason) {
    setTimeout(function () { // 异步执行所有的回调函数
      if (self.status === 'pending') {
        self.status = 'rejected'
        self.data = reason
        for (var i = 0; i < self.onRejectedCallback.length; i++) {
          self.onRejectedCallback[i](reason)
        }
      }
    })
  }

  try {
    executor(resolve, reject)
  } catch (reason) {
    reject(reason)
  }
}

Promise.prototype.then = function (onResolved, onRejected) {
  var self = this
  var promise2

  if (self.status === 'pending') {
    return promise2 = new Promise(function (resolve, reject) {
      self.onResolvedCallback.push(function (value) {
        try {
          resolve(onResolved(value))
        } catch (r) {
          reject(r)
        }
      })
      self.onRejectedCallback.push(function (reason) {
        try {
          resolve(onRejected(reason))
        } catch (r) {
          reject(r)
        }
      })
    })
  }
}

new Promise((resolve, reject) => {
  reject(123);
})
  .then(
    (res) => {
      console.log("成功1", res);
    },
    (err) => {
      console.log("失败1", err);
      return 456
    }
  )
  .then(
    (res) => {
      console.log("成功2", res);
    },
    (err) => {
      console.log("失败2", err);
    }
  );
```
分析如下:<br>
1. 首先`new`一个`Promise`对象的实例
2. Promise内部会初始化实例,将内部的resolve以及reject代入new的时候给的函数中并执行这个函数
3. 接着函数调用`reject`方法(是在Promise对象中定义好的)
4. `reject`方法会记录reason,改变Promise状态,以及循环执行待执行的失败回调. 但这一切操作都是异步的,所以会放在后面才会真正执行
5. 接着就会得到一个`Promise`实例对象,这个对象再调用原型链上定义的`then`方法
6. `then`方法会返回一个新的`Promise`对象,并且在`new`这个新的`Promise`对象的时候会执行以下操作
   1. 往正在执行的(也就是new这个新的Promise对象之前的Promise对象)中的两个回调数组(rejectArr, resolveArr)push进新的Promise的成功或者失败回调函数
   2. 被放入的回调函数中会调用旧的`Promise`成功或者失败的回调,然后再将他们的结果给到新的`Promise`的成功状态中
7. 在得到的新的`Promise`对象后会开始执行第二个`then`方法,这个也会重复上面的过程,注意这个时候新的`Promise`的状态也是`pending`
8. 这个时候开始执行异步队列
9. 首先会执行最初的`reject`产生的异步队列,发现它修改了旧的`Promise`实例的stats以及开始执行回调
10. 由于旧的`Promise`的stats为reject,所以会遍历执行`onRejectedCallback`数组内的方法
11. 发现`onRejectedCallback`数组内只有一个方法,执行它会发现它执行了旧`Promise`的失败回调,并且把这个回调的结果以`resolve`状态给了新的`Promise`
12. 到此就结束了旧的`Promise`的执行,开始第二个`then`的真正执行
13. 因为旧的`Promise`给的是`resolve`状态,所以会开始遍历新的`Promise`的`onResolvedCallback`数组内的方法
14. 同理,会执行新的`Promise`的成功回调,并且把这次的回调结果再次以`resolve`状态给下一个创建的`Promise`,一直传递下去

总结<br>
难理解的就在于正在执行的Promise实例调用的成功回调内的resolve是新的Promise实例的resolve,并且给的参数是本次(也就是旧的)Promise实例的成功回调返回的参数,就是凭借着这个才能通知到新的Promise实例成功还是失败,形成一个链式结构,reject同理!


## 升级版
增加 resolvePromise 方法, 使之能适配所有Promise
``` js
function Promise(executor) {
  var self = this
  self.status = 'pending'
  self.onResolvedCallback = []
  self.onRejectedCallback = []

  function resolve(value) {
    setTimeout(function () { // 异步执行所有的回调函数
      if (self.status === 'pending') {
        self.status = 'resolved'
        self.data = value
        for (var i = 0; i < self.onResolvedCallback.length; i++) {
          self.onResolvedCallback[i](value)
        }
      }
    })
  }
  function reject(reason) {
    setTimeout(function () { // 异步执行所有的回调函数
      if (self.status === 'pending') {
        self.status = 'rejected'
        self.data = reason
        for (var i = 0; i < self.onRejectedCallback.length; i++) {
          self.onRejectedCallback[i](reason)
        }
      }
    })
  }
  try {
    executor(resolve, reject)
  } catch (reason) {
    reject(reason)
  }
}

function resolvePromise(promise2, x, resolve, reject) {
  var then
  var thenCalledOrThrow = false

  if (promise2 === x) {
    return reject(new TypeError('Chaining cycle detected for promise!'))
  }

  if (x instanceof Promise) {
    if (x.status === 'pending') {
      x.then(function (value) {
        resolvePromise(promise2, value, resolve, reject)
      }, reject)
    } else {
      x.then(resolve, reject)
    }
    return
  }

  if ((x !== null) && ((typeof x === 'object') || (typeof x === 'function'))) {
    try {
      then = x.then
      if (typeof then === 'function') {
        then.call(x, function rs(y) {
          if (thenCalledOrThrow) return // 2.3.3.3.3 即这三处谁选执行就以谁的结果为准
          thenCalledOrThrow = true
          return resolvePromise(promise2, y, resolve, reject)
        }, function rj(r) {
          if (thenCalledOrThrow) return // 2.3.3.3.3 即这三处谁选执行就以谁的结果为准
          thenCalledOrThrow = true
          return reject(r)
        })
      } else {
        resolve(x)
      }
    } catch (e) {
      if (thenCalledOrThrow) return // 2.3.3.3.3 即这三处谁选执行就以谁的结果为准
      thenCalledOrThrow = true
      return reject(e)
    }
  } else {
    console.log(666666);
    resolve(x)
  }
}

Promise.prototype.then = function (onResolved, onRejected) {
  var self = this
  var promise2

  if (self.status === 'pending') {
    return promise2 = new Promise(function (resolve, reject) {
      self.onResolvedCallback.push(function (value) {
        try {
          var x = onResolved(value)
          resolvePromise(promise2, x, resolve, reject)
        } catch (r) {
          reject(r)
        }
      })
      self.onRejectedCallback.push(function (reason) {
        try {
          var x = onRejected(reason)
          resolvePromise(promise2, x, resolve, reject)
        } catch (r) {
          reject(r)
        }
      })
    })
  }
}

new Promise((resolve, reject) => {
  resolve(123);
})
  .then(
    (res) => {
      console.log("成功1", res);
      return new Promise((resolve, reject) => {
        console.log('进来了第二层Promise');
        reject('Promise2失败')
      }).then(() => {
        console.log('进来了第三层Promise   成功');
      }, () => {
        console.log('进来了第三层Promise   失败');
      })
    },
    (err) => {
      console.log("失败1", err);
    }
  )
  .then(
    (res) => {
      console.log("成功2", res);
    },
    (err) => {
      console.log("失败2", err);
    }
  );
```
分析如下:<br>
1. 首先这边加入了`resolvePromise`方法，为的是能适应所有的Promise，比如说自己写的Promise能和axios的Promise互通，这一点很重要
2. 因为有了`resolvePromise`方法，我们这边在then里面嵌入了新的Promise的操作，以达到真实使用场景,下面就正式开始吧
3. ![Promise图解](https://gitee.com/M-cheng-web/map-storage/raw/master/workspace-img/20210819081009.png)

4. 首先得到Promise1，并且执行了内部的`resolve(123)`方法，只不过这个方法是异步的，所以会先执行后面跟着的两个then方法
5. 执行第一个then方法，得到Promise2，并且执行内部的流程，注意，这个时候的内部self指向的是Promise1，也就是往Promise1中的收集器放入了待执行的方法
6. 执行第二个then方法，得到Promise5，并且执行内部的流程，这个时候的内部self指向Promise2，也就是往Promise2中的收集器放入了待执行的方法
7. 真正开始执行`resolve(123)`
8. 触发Promise2中的成功的代码块并执行
9. 执行new Promise操作，并执行内部代码 reject('Promise2失败')(异步的)，
10. 执行Prmoise3 的then方法，它内部的self是指向Promise3的，也就是往Promise3的收集器放入了待执行的方法
11. Prmoise3 的then方法会返回 Promise4，这就是说在Promise3的代码块中实际上返回的是 Promise4这个Promise实例，这一点很重要
12. 饶了一大圈，终于能回到最开始的成功收集器的步骤了(也就是第一个then方法触发的成功回调，不要忘记了，它是没有执行完的)
13. 这个时候返回的Promise4就是x
14. 然后会执行 `resolvePromise(promise2, x, resolve, reject)`，这里的promise2指的是Promise2，x指的是Promise4，resolve和reject是Promise2的方法
15. 进入`resolvePromise`会发现x是Promise实例，于是会执行Promise4的then方法，往Promise4的收集器中放入了待执行的方法
16. 上面要注意resolve和reject是Promise2的方法，意思就是当有任何地方调用了这俩其中一个，就是结束了Prmoise2的pendding状态，就会开始下一个then
17. 发现到现在貌似都执行完了，还记得上面的 reject('Promise2失败') 方法不，这东西该开始真正执行了
18. 它会触发Promise3的失败收集器，也就是会执行 console.log('进来了第三层Promise   失败')
19. 然后会将这个函数运行的结果赋值给x(很显然这个打印函数只会返回undefined)
20. 然后会执行 `resolvePromise(promise2, x, resolve, reject)`，这里的promise2指的是Promise4，x是undefined，resolve和reject是Promise4的方法
21. 由于x是undefined，所以会执行Promise4的resolve(undefined)
22. 这样又会触发Promise4的成功收集器(之前往Promise4的收集器中放了东西滴)
23. 然后又会触发Promise2的resolve(undefined)
24. 最终会触发Promise5的成功收集器





























